<?xml version="1.0" ?>
<robot name="gummi">
	<link name="base_link"/>
	<joint name="set_worldaxis" type="fixed">
		<origin rpy="1.570796326795 0 0" xyz="0.0 0.0 0.0"/>
		<parent link="base_link"/>
		<child link="base"/>
		<axis xyz="0 0 0"/>
		<limit effort="0" lower="-1" upper="1" velocity="0"/>
	</joint>
	<link name="base">
		<inertial>
			<origin rpy="0.0 0.0 0.0" xyz="0.0 0.0 0.0"/>
			<mass value="0"/>
			<inertia ixx="0" ixy="0" ixz="0" iyy="0" iyz="0" izz="0"/>
		</inertial>
		<visual>
			<origin rpy="0.0 0.0 0.0" xyz="0.0 0.0 0.0"/>
			<geometry>
				<mesh filename="package://wheelchair/meshes/base.stl"/>
			</geometry>
			<material name="">
				<color rgba="0.792156862745098 0.819607843137255 0.933333333333333 1"/>
			</material>
		</visual>
		<collision>
			<origin rpy="0.0 0.0 0.0" xyz="0.0 0.0 0.0"/>
			<geometry>
				<mesh filename="package://wheelchair/meshes/base.stl"/>
			</geometry>
		</collision>
	</link>
	<link name="link1">
		<inertial>
			<origin rpy="0.0 0.0 0.0" xyz="0.0 0.0 0.0"/>
			<mass value="0"/>
			<inertia ixx="0" ixy="0" ixz="0" iyy="0" iyz="0" izz="0"/>
		</inertial>
		<visual>
			<origin rpy="0.0 0.0 0.0" xyz="0.0 0.0 0.0"/>
			<geometry>
				<mesh filename="package://wheelchair/meshes/link1.stl"/>
			</geometry>
			<material name="">
				<color rgba="0.792156862745098 0.819607843137255 0.933333333333333 1"/>
			</material>
		</visual>
		<collision>
			<origin rpy="0.0 0.0 0.0" xyz="0.0 0.0 0.0"/>
			<geometry>
				<mesh filename="package://wheelchair/meshes/link1.stl"/>
			</geometry>
		</collision>
	</link>
	<link name="link2">
		<inertial>
			<origin rpy="0.0 0.0 0.0" xyz="0.0 0.0 0.0"/>
			<mass value="0"/>
			<inertia ixx="0" ixy="0" ixz="0" iyy="0" iyz="0" izz="0"/>
		</inertial>
		<visual>
			<origin rpy="0.0 0.0 0.0" xyz="0.0 0.0 0.0"/>
			<geometry>
				<mesh filename="package://wheelchair/meshes/link2.stl"/>
			</geometry>
			<material name="">
				<color rgba="0.792156862745098 0.819607843137255 0.933333333333333 1"/>
			</material>
		</visual>
		<collision>
			<origin rpy="0.0 0.0 0.0" xyz="0.0 0.0 0.0"/>
			<geometry>
				<mesh filename="package://wheelchair/meshes/link2.stl"/>
			</geometry>
		</collision>
	</link>
	<joint name="joint1" type="continuous">
		<origin rpy="0.0 0.0 0.0" xyz="0.6162001603339797 0.9987983990460869 -0.10515639316991093"/>
		<parent link="base"/>
		<child link="link1"/>
		<axis xyz="-0.9698848187392894 0.24356401227352137 0.00010151002393613432"/>
		<limit effort="0" lower="-1" upper="1" velocity="0"/>
	</joint>
	<joint name="joint2" type="continuous">
		<origin rpy="0.0 0.0 0.0" xyz="-0.05333534440670149 0.013396020675043162 0.07950558261589771"/>
		<parent link="link1"/>
		<child link="link2"/>
		<axis xyz="-0.00010466193655742605 -1.1955594058051162e-14 -0.99999999452302"/>
		<limit effort="0" lower="-1" upper="1" velocity="0"/>
	</joint>
</robot>

