<?xml version="1.0" ?>
<!-- =================================================================================== -->
<!-- |    This document was autogenerated by xacro from SARA.xacro                     | -->
<!-- |    EDITING THIS FILE BY HAND IS NOT RECOMMENDED                                 | -->
<!-- =================================================================================== -->
<robot name="SARA" xmlns:xacro="http://www.ros.org/wiki/xacro">
  <!-- "xacro inorder SARA.xacro > SARA.urdf" -->
  <!-- First segment -->
  <link name="world"/>
  <!-- ${link_name} -->
  <!--*********************************************************************************-->
  <link name="base_link">
    <inertial>
      <origin rpy="0.0 0.0 0.0" xyz="0.0 0.0 0.0"/>
      <mass value="1.0"/>
      <inertia ixx="0.04" ixy="0.04" ixz="0.04" iyy="0.04" iyz="0.04" izz="0.04"/>
    </inertial>
    <visual>
      <origin rpy="0.0 0.0 0.0" xyz="0.0 0.0 0.0"/>
      <geometry>
        <mesh filename="package://sara_8dof_v1/meshes/base_link.stl"/>
      </geometry>
      <material name="">
        <color rgba="0.792156862745098 0.819607843137255 0.933333333333333 1"/>
      </material>
    </visual>
    <collision>
      <origin rpy="0.0 0.0 0.0" xyz="0.0 0.0 0.0"/>
      <geometry>
        <mesh filename="package://sara_8dof_v1/meshes/base_link.stl"/>
      </geometry>
    </collision>
  </link>
  <!--*********************************************************************************-->
  <!-- ${link_name} -->
  <!--*********************************************************************************-->
  <link name="link1">
    <inertial>
      <origin rpy="0.0 0.0 0.0" xyz="0.0 0.0 0.0"/>
      <mass value="1.0"/>
      <inertia ixx="0.04" ixy="0.04" ixz="0.04" iyy="0.04" iyz="0.04" izz="0.04"/>
    </inertial>
    <visual>
      <origin rpy="0.0 0.0 0.0" xyz="0.0 0.0 0.0"/>
      <geometry>
        <mesh filename="package://sara_8dof_v1/meshes/link1.stl"/>
      </geometry>
      <material name="">
        <color rgba="0.792156862745098 0.819607843137255 0.933333333333333 1"/>
      </material>
    </visual>
    <collision>
      <origin rpy="0.0 0.0 0.0" xyz="0.0 0.0 0.0"/>
      <geometry>
        <mesh filename="package://sara_8dof_v1/meshes/link1.stl"/>
      </geometry>
    </collision>
  </link>
  <!--*********************************************************************************-->
  <!-- ${link_name} -->
  <!--*********************************************************************************-->
  <link name="link2">
    <inertial>
      <origin rpy="0.0 0.0 0.0" xyz="0.0 0.0 0.0"/>
      <mass value="1.0"/>
      <inertia ixx="0.04" ixy="0.04" ixz="0.04" iyy="0.04" iyz="0.04" izz="0.04"/>
    </inertial>
    <visual>
      <origin rpy="0.0 0.0 0.0" xyz="0.0 0.0 0.0"/>
      <geometry>
        <mesh filename="package://sara_8dof_v1/meshes/link2.stl"/>
      </geometry>
      <material name="">
        <color rgba="0.792156862745098 0.819607843137255 0.933333333333333 1"/>
      </material>
    </visual>
    <collision>
      <origin rpy="0.0 0.0 0.0" xyz="0.0 0.0 0.0"/>
      <geometry>
        <mesh filename="package://sara_8dof_v1/meshes/link2.stl"/>
      </geometry>
    </collision>
  </link>
  <!--*********************************************************************************-->
  <joint name="world_frame" type="fixed">
    <origin rpy="1.57079632679 0 0" xyz="0.0 0.0 0.01"/>
    <parent link="world"/>
    <child link="base_link"/>
  </joint>
  <!-- joint${joint_num#} -->
  <!--*********************************************************************************-->
  <joint name="joint0" type="revolute">
    <parent link="base_link"/>
    <child link="link1"/>
    <origin rpy="0.0 0.0 0.0" xyz="0.0431603651232 0.0484824520656 0.0274545091047"/>
    <axis xyz="-1.0 0.0 0.0"/>
    <limit effort="30" lower="-0.7853981633974483" upper="0.7853981633974483" velocity="1.0"/>
    <dynamics damping="0.0" friction="10.0"/>
  </joint>
  <transmission name="tran0">
    <type>transmission_interface/SimpleTransmission</type>
    <joint name="joint0">
      <hardwareInterface>hardware_interface/EffortJointInterface</hardwareInterface>
    </joint>
    <actuator name="motor0">
      <hardwareInterface>hardware_interface/EffortJointInterface</hardwareInterface>
      <mechanicalReduction>1</mechanicalReduction>
    </actuator>
  </transmission>
  <!--*********************************************************************************-->
  <!-- joint${joint_num#} -->
  <!--*********************************************************************************-->
  <joint name="joint1" type="revolute">
    <parent link="link1"/>
    <child link="link2"/>
    <origin rpy="0.0 0.0 0.0" xyz="-0.01655 0.040054 -0.0121"/>
    <axis xyz="0.0 0.0 1.0"/>
    <limit effort="30" lower="-0.7853981633974483" upper="0.7853981633974483" velocity="1.0"/>
    <dynamics damping="0.0" friction="10.0"/>
  </joint>
  <transmission name="tran1">
    <type>transmission_interface/SimpleTransmission</type>
    <joint name="joint1">
      <hardwareInterface>hardware_interface/EffortJointInterface</hardwareInterface>
    </joint>
    <actuator name="motor1">
      <hardwareInterface>hardware_interface/EffortJointInterface</hardwareInterface>
      <mechanicalReduction>1</mechanicalReduction>
    </actuator>
  </transmission>
  <!--*********************************************************************************-->
  <!-- ${link_name} -->
  <!--*********************************************************************************-->
  <link name="link3">
    <inertial>
      <origin rpy="0.0 0.0 0.0" xyz="0.0 0.0 0.0"/>
      <mass value="1.0"/>
      <inertia ixx="0.04" ixy="0.04" ixz="0.04" iyy="0.04" iyz="0.04" izz="0.04"/>
    </inertial>
    <visual>
      <origin rpy="0.0 0.0 0.0" xyz="0.0 0.0 0.0"/>
      <geometry>
        <mesh filename="package://sara_8dof_v1/meshes/base_link.stl"/>
      </geometry>
      <material name="">
        <color rgba="0.792156862745098 0.819607843137255 0.933333333333333 1"/>
      </material>
    </visual>
    <collision>
      <origin rpy="0.0 0.0 0.0" xyz="0.0 0.0 0.0"/>
      <geometry>
        <mesh filename="package://sara_8dof_v1/meshes/base_link.stl"/>
      </geometry>
    </collision>
  </link>
  <!--*********************************************************************************-->
  <!-- ${link_name} -->
  <!--*********************************************************************************-->
  <link name="link4">
    <inertial>
      <origin rpy="0.0 0.0 0.0" xyz="0.0 0.0 0.0"/>
      <mass value="1.0"/>
      <inertia ixx="0.04" ixy="0.04" ixz="0.04" iyy="0.04" iyz="0.04" izz="0.04"/>
    </inertial>
    <visual>
      <origin rpy="0.0 0.0 0.0" xyz="0.0 0.0 0.0"/>
      <geometry>
        <mesh filename="package://sara_8dof_v1/meshes/link1.stl"/>
      </geometry>
      <material name="">
        <color rgba="0.792156862745098 0.819607843137255 0.933333333333333 1"/>
      </material>
    </visual>
    <collision>
      <origin rpy="0.0 0.0 0.0" xyz="0.0 0.0 0.0"/>
      <geometry>
        <mesh filename="package://sara_8dof_v1/meshes/link1.stl"/>
      </geometry>
    </collision>
  </link>
  <!--*********************************************************************************-->
  <!-- ${link_name} -->
  <!--*********************************************************************************-->
  <link name="link5">
    <inertial>
      <origin rpy="0.0 0.0 0.0" xyz="0.0 0.0 0.0"/>
      <mass value="1.0"/>
      <inertia ixx="0.04" ixy="0.04" ixz="0.04" iyy="0.04" iyz="0.04" izz="0.04"/>
    </inertial>
    <visual>
      <origin rpy="0.0 0.0 0.0" xyz="0.0 0.0 0.0"/>
      <geometry>
        <mesh filename="package://sara_8dof_v1/meshes/link2.stl"/>
      </geometry>
      <material name="">
        <color rgba="0.792156862745098 0.819607843137255 0.933333333333333 1"/>
      </material>
    </visual>
    <collision>
      <origin rpy="0.0 0.0 0.0" xyz="0.0 0.0 0.0"/>
      <geometry>
        <mesh filename="package://sara_8dof_v1/meshes/link2.stl"/>
      </geometry>
    </collision>
  </link>
  <!--*********************************************************************************-->
  <joint name="second_segment_base" type="fixed">
    <origin rpy="0 0 0" xyz="-0.02661 0.025554 -0.0153545"/>
    <parent link="link2"/>
    <child link="link3"/>
  </joint>
  <!-- joint${joint_num#} -->
  <!--*********************************************************************************-->
  <joint name="joint2" type="revolute">
    <parent link="link3"/>
    <child link="link4"/>
    <origin rpy="0.0 0.0 0.0" xyz="0.0431603651232 0.0484824520656 0.0274545091047"/>
    <axis xyz="-1.0 0.0 0.0"/>
    <limit effort="30" lower="-0.7853981633974483" upper="0.7853981633974483" velocity="1.0"/>
    <dynamics damping="0.0" friction="10.0"/>
  </joint>
  <transmission name="tran2">
    <type>transmission_interface/SimpleTransmission</type>
    <joint name="joint2">
      <hardwareInterface>hardware_interface/EffortJointInterface</hardwareInterface>
    </joint>
    <actuator name="motor2">
      <hardwareInterface>hardware_interface/EffortJointInterface</hardwareInterface>
      <mechanicalReduction>1</mechanicalReduction>
    </actuator>
  </transmission>
  <!--*********************************************************************************-->
  <!-- joint${joint_num#} -->
  <!--*********************************************************************************-->
  <joint name="joint3" type="revolute">
    <parent link="link4"/>
    <child link="link5"/>
    <origin rpy="0.0 0.0 0.0" xyz="-0.01655 0.040054 -0.0121"/>
    <axis xyz="0.0 0.0 1.0"/>
    <limit effort="30" lower="-0.7853981633974483" upper="0.7853981633974483" velocity="1.0"/>
    <dynamics damping="0.0" friction="10.0"/>
  </joint>
  <transmission name="tran3">
    <type>transmission_interface/SimpleTransmission</type>
    <joint name="joint3">
      <hardwareInterface>hardware_interface/EffortJointInterface</hardwareInterface>
    </joint>
    <actuator name="motor3">
      <hardwareInterface>hardware_interface/EffortJointInterface</hardwareInterface>
      <mechanicalReduction>1</mechanicalReduction>
    </actuator>
  </transmission>
  <!--*********************************************************************************-->
  <!-- ${link_name} -->
  <!--*********************************************************************************-->
  <link name="link6">
    <inertial>
      <origin rpy="0.0 0.0 0.0" xyz="0.0 0.0 0.0"/>
      <mass value="1.0"/>
      <inertia ixx="0.04" ixy="0.04" ixz="0.04" iyy="0.04" iyz="0.04" izz="0.04"/>
    </inertial>
    <visual>
      <origin rpy="0.0 0.0 0.0" xyz="0.0 0.0 0.0"/>
      <geometry>
        <mesh filename="package://sara_8dof_v1/meshes/base_link.stl"/>
      </geometry>
      <material name="">
        <color rgba="0.792156862745098 0.819607843137255 0.933333333333333 1"/>
      </material>
    </visual>
    <collision>
      <origin rpy="0.0 0.0 0.0" xyz="0.0 0.0 0.0"/>
      <geometry>
        <mesh filename="package://sara_8dof_v1/meshes/base_link.stl"/>
      </geometry>
    </collision>
  </link>
  <!--*********************************************************************************-->
  <!-- ${link_name} -->
  <!--*********************************************************************************-->
  <link name="link7">
    <inertial>
      <origin rpy="0.0 0.0 0.0" xyz="0.0 0.0 0.0"/>
      <mass value="1.0"/>
      <inertia ixx="0.04" ixy="0.04" ixz="0.04" iyy="0.04" iyz="0.04" izz="0.04"/>
    </inertial>
    <visual>
      <origin rpy="0.0 0.0 0.0" xyz="0.0 0.0 0.0"/>
      <geometry>
        <mesh filename="package://sara_8dof_v1/meshes/link1.stl"/>
      </geometry>
      <material name="">
        <color rgba="0.792156862745098 0.819607843137255 0.933333333333333 1"/>
      </material>
    </visual>
    <collision>
      <origin rpy="0.0 0.0 0.0" xyz="0.0 0.0 0.0"/>
      <geometry>
        <mesh filename="package://sara_8dof_v1/meshes/link1.stl"/>
      </geometry>
    </collision>
  </link>
  <!--*********************************************************************************-->
  <!-- ${link_name} -->
  <!--*********************************************************************************-->
  <link name="link8">
    <inertial>
      <origin rpy="0.0 0.0 0.0" xyz="0.0 0.0 0.0"/>
      <mass value="1.0"/>
      <inertia ixx="0.04" ixy="0.04" ixz="0.04" iyy="0.04" iyz="0.04" izz="0.04"/>
    </inertial>
    <visual>
      <origin rpy="0.0 0.0 0.0" xyz="0.0 0.0 0.0"/>
      <geometry>
        <mesh filename="package://sara_8dof_v1/meshes/link2.stl"/>
      </geometry>
      <material name="">
        <color rgba="0.792156862745098 0.819607843137255 0.933333333333333 1"/>
      </material>
    </visual>
    <collision>
      <origin rpy="0.0 0.0 0.0" xyz="0.0 0.0 0.0"/>
      <geometry>
        <mesh filename="package://sara_8dof_v1/meshes/link2.stl"/>
      </geometry>
    </collision>
  </link>
  <!--*********************************************************************************-->
  <joint name="third_segment_base" type="fixed">
    <origin rpy="0 0 0" xyz="-0.02661 0.025554 -0.0153545"/>
    <parent link="link5"/>
    <child link="link6"/>
  </joint>
  <!-- joint${joint_num#} -->
  <!--*********************************************************************************-->
  <joint name="joint4" type="revolute">
    <parent link="link6"/>
    <child link="link7"/>
    <origin rpy="0.0 0.0 0.0" xyz="0.0431603651232 0.0484824520656 0.0274545091047"/>
    <axis xyz="-1.0 0.0 0.0"/>
    <limit effort="30" lower="-0.7853981633974483" upper="0.7853981633974483" velocity="1.0"/>
    <dynamics damping="0.0" friction="10.0"/>
  </joint>
  <transmission name="tran4">
    <type>transmission_interface/SimpleTransmission</type>
    <joint name="joint4">
      <hardwareInterface>hardware_interface/EffortJointInterface</hardwareInterface>
    </joint>
    <actuator name="motor4">
      <hardwareInterface>hardware_interface/EffortJointInterface</hardwareInterface>
      <mechanicalReduction>1</mechanicalReduction>
    </actuator>
  </transmission>
  <!--*********************************************************************************-->
  <!-- joint${joint_num#} -->
  <!--*********************************************************************************-->
  <joint name="joint5" type="revolute">
    <parent link="link7"/>
    <child link="link8"/>
    <origin rpy="0.0 0.0 0.0" xyz="-0.01655 0.040054 -0.0121"/>
    <axis xyz="0.0 0.0 1.0"/>
    <limit effort="30" lower="-0.7853981633974483" upper="0.7853981633974483" velocity="1.0"/>
    <dynamics damping="0.0" friction="10.0"/>
  </joint>
  <transmission name="tran5">
    <type>transmission_interface/SimpleTransmission</type>
    <joint name="joint5">
      <hardwareInterface>hardware_interface/EffortJointInterface</hardwareInterface>
    </joint>
    <actuator name="motor5">
      <hardwareInterface>hardware_interface/EffortJointInterface</hardwareInterface>
      <mechanicalReduction>1</mechanicalReduction>
    </actuator>
  </transmission>
  <!--*********************************************************************************-->
  <!-- ${link_name} -->
  <!--*********************************************************************************-->
  <link name="link9">
    <inertial>
      <origin rpy="0.0 0.0 0.0" xyz="0.0 0.0 0.0"/>
      <mass value="1.0"/>
      <inertia ixx="0.04" ixy="0.04" ixz="0.04" iyy="0.04" iyz="0.04" izz="0.04"/>
    </inertial>
    <visual>
      <origin rpy="0.0 0.0 0.0" xyz="0.0 0.0 0.0"/>
      <geometry>
        <mesh filename="package://sara_8dof_v1/meshes/base_link.stl"/>
      </geometry>
      <material name="">
        <color rgba="0.792156862745098 0.819607843137255 0.933333333333333 1"/>
      </material>
    </visual>
    <collision>
      <origin rpy="0.0 0.0 0.0" xyz="0.0 0.0 0.0"/>
      <geometry>
        <mesh filename="package://sara_8dof_v1/meshes/base_link.stl"/>
      </geometry>
    </collision>
  </link>
  <!--*********************************************************************************-->
  <!-- ${link_name} -->
  <!--*********************************************************************************-->
  <link name="link10">
    <inertial>
      <origin rpy="0.0 0.0 0.0" xyz="0.0 0.0 0.0"/>
      <mass value="1.0"/>
      <inertia ixx="0.04" ixy="0.04" ixz="0.04" iyy="0.04" iyz="0.04" izz="0.04"/>
    </inertial>
    <visual>
      <origin rpy="0.0 0.0 0.0" xyz="0.0 0.0 0.0"/>
      <geometry>
        <mesh filename="package://sara_8dof_v1/meshes/link1.stl"/>
      </geometry>
      <material name="">
        <color rgba="0.792156862745098 0.819607843137255 0.933333333333333 1"/>
      </material>
    </visual>
    <collision>
      <origin rpy="0.0 0.0 0.0" xyz="0.0 0.0 0.0"/>
      <geometry>
        <mesh filename="package://sara_8dof_v1/meshes/link1.stl"/>
      </geometry>
    </collision>
  </link>
  <!--*********************************************************************************-->
  <!-- ${link_name} -->
  <!--*********************************************************************************-->
  <link name="link11">
    <inertial>
      <origin rpy="0.0 0.0 0.0" xyz="0.0 0.0 0.0"/>
      <mass value="1.0"/>
      <inertia ixx="0.04" ixy="0.04" ixz="0.04" iyy="0.04" iyz="0.04" izz="0.04"/>
    </inertial>
    <visual>
      <origin rpy="0.0 0.0 0.0" xyz="0.0 0.0 0.0"/>
      <geometry>
        <mesh filename="package://sara_8dof_v1/meshes/link2.stl"/>
      </geometry>
      <material name="">
        <color rgba="0.792156862745098 0.819607843137255 0.933333333333333 1"/>
      </material>
    </visual>
    <collision>
      <origin rpy="0.0 0.0 0.0" xyz="0.0 0.0 0.0"/>
      <geometry>
        <mesh filename="package://sara_8dof_v1/meshes/link2.stl"/>
      </geometry>
    </collision>
  </link>
  <!--*********************************************************************************-->
  <joint name="fourth_segment_base" type="fixed">
    <origin rpy="0 0 0" xyz="-0.02661 0.025554 -0.0153545"/>
    <parent link="link8"/>
    <child link="link9"/>
  </joint>
  <!-- joint${joint_num#} -->
  <!--*********************************************************************************-->
  <joint name="joint6" type="revolute">
    <parent link="link9"/>
    <child link="link10"/>
    <origin rpy="0.0 0.0 0.0" xyz="0.0431603651232 0.0484824520656 0.0274545091047"/>
    <axis xyz="-1.0 0.0 0.0"/>
    <limit effort="30" lower="-0.7853981633974483" upper="0.7853981633974483" velocity="1.0"/>
    <dynamics damping="0.0" friction="10.0"/>
  </joint>
  <transmission name="tran6">
    <type>transmission_interface/SimpleTransmission</type>
    <joint name="joint6">
      <hardwareInterface>hardware_interface/EffortJointInterface</hardwareInterface>
    </joint>
    <actuator name="motor6">
      <hardwareInterface>hardware_interface/EffortJointInterface</hardwareInterface>
      <mechanicalReduction>1</mechanicalReduction>
    </actuator>
  </transmission>
  <!--*********************************************************************************-->
  <!-- joint${joint_num#} -->
  <!--*********************************************************************************-->
  <joint name="joint7" type="revolute">
    <parent link="link10"/>
    <child link="link11"/>
    <origin rpy="0.0 0.0 0.0" xyz="-0.01655 0.040054 -0.0121"/>
    <axis xyz="0.0 0.0 1.0"/>
    <limit effort="30" lower="-0.7853981633974483" upper="0.7853981633974483" velocity="1.0"/>
    <dynamics damping="0.0" friction="10.0"/>
  </joint>
  <transmission name="tran7">
    <type>transmission_interface/SimpleTransmission</type>
    <joint name="joint7">
      <hardwareInterface>hardware_interface/EffortJointInterface</hardwareInterface>
    </joint>
    <actuator name="motor7">
      <hardwareInterface>hardware_interface/EffortJointInterface</hardwareInterface>
      <mechanicalReduction>1</mechanicalReduction>
    </actuator>
  </transmission>
  <!--*********************************************************************************-->
  <!-- 
		 Gazebo plugins: 

			ros_control
			* Accepts new desired trajectories via follow_joint_trajectory, while joint_state_publisher publishes joint_states.
			* Makes joints move.

			joint_state_publisher
			* Publish current state of each joint to a topic 
	-->
  <gazebo>
    <plugin filename="libgazebo_ros_control.so" name="control">
      <robotNamespace>/SARA</robotNamespace>
    </plugin>
    <plugin filename="libgazebo_ros_joint_state_publisher.so" name="joint_state_publisher">
      <jointName>joint0, joint1, joint2, joint3, joint4, joint5, joint6, joint7</jointName>
      <updateRate>100.0</updateRate>
      <alwaysOn>true</alwaysOn>
      <!-- <robotNamespace>/SARA</robotNamespace> -->
    </plugin>
  </gazebo>
</robot>

